{"uuid": "221972da-b84e-4295-8c08-6c6c588443dc", "children": ["f8d27fc1-4555-4e25-aa97-5eb9403b77a4"], "befores": [{"name": "init_app", "status": "broken", "statusDetails": {"message": "urllib3.exceptions.MaxRetryError: HTTPConnectionPool(host='127.0.0.1', port=4444): Max retries exceeded with url: /wd/hub/session (Caused by NewConnectionError('<urllib3.connection.HTTPConnection object at 0x0000000004DF60B8>: Failed to establish a new connection: [WinError 10061] 由于目标计算机积极拒绝，无法连接。'))\n", "trace": "  File \"C:\\Program Files\\Python37\\lib\\site-packages\\pluggy\\callers.py\", line 187, in _multicall\n    res = hook_impl.function(*args)\n  File \"C:\\Program Files\\Python37\\lib\\site-packages\\_pytest\\fixtures.py\", line 918, in pytest_fixture_setup\n    result = call_fixture_func(fixturefunc, request, kwargs)\n  File \"C:\\Program Files\\Python37\\lib\\site-packages\\_pytest\\fixtures.py\", line 774, in call_fixture_func\n    res = next(it)\n  File \"D:\\code\\app_test\\conftest.py\", line 15, in init_app\n    driver = Remote(desired_capabilities=caps)\n  File \"C:\\Program Files\\Python37\\lib\\site-packages\\appium\\webdriver\\webdriver.py\", line 144, in __init__\n    proxy\n  File \"C:\\Program Files\\Python37\\lib\\selenium\\webdriver\\remote\\webdriver.py\", line 157, in __init__\n    self.start_session(capabilities, browser_profile)\n  File \"C:\\Program Files\\Python37\\lib\\site-packages\\appium\\webdriver\\webdriver.py\", line 219, in start_session\n    response = self.execute(RemoteCommand.NEW_SESSION, parameters)\n  File \"C:\\Program Files\\Python37\\lib\\selenium\\webdriver\\remote\\webdriver.py\", line 319, in execute\n    response = self.command_executor.execute(driver_command, params)\n  File \"C:\\Program Files\\Python37\\lib\\selenium\\webdriver\\remote\\remote_connection.py\", line 374, in execute\n    return self._request(command_info[0], url, body=data)\n  File \"C:\\Program Files\\Python37\\lib\\selenium\\webdriver\\remote\\remote_connection.py\", line 397, in _request\n    resp = self._conn.request(method, url, body=body, headers=headers)\n  File \"C:\\Program Files\\Python37\\lib\\urllib3\\request.py\", line 72, in request\n    **urlopen_kw)\n  File \"C:\\Program Files\\Python37\\lib\\urllib3\\request.py\", line 150, in request_encode_body\n    return self.urlopen(method, url, **extra_kw)\n  File \"C:\\Program Files\\Python37\\lib\\urllib3\\poolmanager.py\", line 323, in urlopen\n    response = conn.urlopen(method, u.request_uri, **kw)\n  File \"C:\\Program Files\\Python37\\lib\\urllib3\\connectionpool.py\", line 667, in urlopen\n    **response_kw)\n  File \"C:\\Program Files\\Python37\\lib\\urllib3\\connectionpool.py\", line 667, in urlopen\n    **response_kw)\n  File \"C:\\Program Files\\Python37\\lib\\urllib3\\connectionpool.py\", line 667, in urlopen\n    **response_kw)\n  File \"C:\\Program Files\\Python37\\lib\\urllib3\\connectionpool.py\", line 638, in urlopen\n    _stacktrace=sys.exc_info()[2])\n  File \"C:\\Program Files\\Python37\\lib\\urllib3\\util\\retry.py\", line 398, in increment\n    raise MaxRetryError(_pool, url, error or ResponseError(cause))\n"}, "start": 1569403492704, "stop": 1569403497707}], "start": 1569403492704, "stop": 1569403497874}