{"uuid": "b42671e4-d58c-4c8c-8a5b-e11bfab50b9a", "children": ["f1ada31e-3252-490a-885e-6ecbdb6f66a7"], "befores": [{"name": "init_app", "status": "broken", "statusDetails": {"message": "urllib3.exceptions.MaxRetryError: HTTPConnectionPool(host='127.0.0.1', port=4444): Max retries exceeded with url: /wd/hub/session (Caused by NewConnectionError('<urllib3.connection.HTTPConnection object at 0x0000000004BD8588>: Failed to establish a new connection: [WinError 10061] 由于目标计算机积极拒绝，无法连接。'))\n", "trace": "  File \"C:\\Program Files\\Python37\\lib\\site-packages\\pluggy\\callers.py\", line 187, in _multicall\n    res = hook_impl.function(*args)\n  File \"C:\\Program Files\\Python37\\lib\\site-packages\\_pytest\\fixtures.py\", line 918, in pytest_fixture_setup\n    result = call_fixture_func(fixturefunc, request, kwargs)\n  File \"C:\\Program Files\\Python37\\lib\\site-packages\\_pytest\\fixtures.py\", line 774, in call_fixture_func\n    res = next(it)\n  File \"D:\\code\\app_test\\conftest.py\", line 15, in init_app\n    driver = Remote(desired_capabilities=caps)\n  File \"C:\\Program Files\\Python37\\lib\\site-packages\\appium\\webdriver\\webdriver.py\", line 144, in __init__\n    proxy\n  File \"C:\\Program Files\\Python37\\lib\\selenium\\webdriver\\remote\\webdriver.py\", line 157, in __init__\n    self.start_session(capabilities, browser_profile)\n  File \"C:\\Program Files\\Python37\\lib\\site-packages\\appium\\webdriver\\webdriver.py\", line 219, in start_session\n    response = self.execute(RemoteCommand.NEW_SESSION, parameters)\n  File \"C:\\Program Files\\Python37\\lib\\selenium\\webdriver\\remote\\webdriver.py\", line 319, in execute\n    response = self.command_executor.execute(driver_command, params)\n  File \"C:\\Program Files\\Python37\\lib\\selenium\\webdriver\\remote\\remote_connection.py\", line 374, in execute\n    return self._request(command_info[0], url, body=data)\n  File \"C:\\Program Files\\Python37\\lib\\selenium\\webdriver\\remote\\remote_connection.py\", line 397, in _request\n    resp = self._conn.request(method, url, body=body, headers=headers)\n  File \"C:\\Program Files\\Python37\\lib\\urllib3\\request.py\", line 72, in request\n    **urlopen_kw)\n  File \"C:\\Program Files\\Python37\\lib\\urllib3\\request.py\", line 150, in request_encode_body\n    return self.urlopen(method, url, **extra_kw)\n  File \"C:\\Program Files\\Python37\\lib\\urllib3\\poolmanager.py\", line 323, in urlopen\n    response = conn.urlopen(method, u.request_uri, **kw)\n  File \"C:\\Program Files\\Python37\\lib\\urllib3\\connectionpool.py\", line 667, in urlopen\n    **response_kw)\n  File \"C:\\Program Files\\Python37\\lib\\urllib3\\connectionpool.py\", line 667, in urlopen\n    **response_kw)\n  File \"C:\\Program Files\\Python37\\lib\\urllib3\\connectionpool.py\", line 667, in urlopen\n    **response_kw)\n  File \"C:\\Program Files\\Python37\\lib\\urllib3\\connectionpool.py\", line 638, in urlopen\n    _stacktrace=sys.exc_info()[2])\n  File \"C:\\Program Files\\Python37\\lib\\urllib3\\util\\retry.py\", line 398, in increment\n    raise MaxRetryError(_pool, url, error or ResponseError(cause))\n"}, "start": 1569403508238, "stop": 1569403513241}], "start": 1569403508238, "stop": 1569403513418}